Running Move unit tests
[ PASS    ] 0x1::M::no_timeout
[ FAIL    ] 0x1::M::no_timeout_fail
[ PASS    ] 0x1::M::no_timeout_while_loop
[ TIMEOUT ] 0x1::M::timeout_fail
[ PASS    ] 0x1::M::timeout_fail_with_expected_failure

Test failures:

Failures in 0x1::M:

┌── no_timeout_fail ──────
│ error[E11001]: test failure
│    ┌─ timeout.move:18:29
│    │
│ 18 │     fun no_timeout_fail() { abort 0 }
│    │         ---------------     ^^^^^^^ Test was not expected to error, but it aborted with code 0 originating in the module 0x1::M rooted here
│    │         │                    
│    │         In this function in 0x1::M
│ 
│ 
└──────────────────


┌── timeout_fail ──────
│ Test timed out
└──────────────────

Test result: FAILED. Total tests: 5; passed: 3; failed: 2
